Workbook

Sheet Fluxo Diário
A1: Data | B1: Categoria | C1: Subcategoria | D1: Descrição | E1: Entrada R$ | F1: Saída R$ | G1: Saldo Acumulado R$
A2: 46081 | B2: Fornecedor | C2: Bebidas | D2: Distribuidora Norte | F2: 4247.26 | G2: =IFERROR(E2,0)-IFERROR(F2,0)
A3: 46082 | B3: Despesa variável | C3: Comissão | D3: Comissão garçom (dom) | F3: 1114.42 | G3: =G2+IFERROR(E3,0)-IFERROR(F3,0)
A4: 46082 | B4: Receita | C4: Cartão crédito | D4: Vendas do dia (dom) | E4: 6838.71 | G4: =G3+IFERROR(E4,0)-IFERROR(F4,0)
A5: 46082 | B5: Receita | C5: Cartão débito | D5: Vendas do dia (dom) | E5: 3343.37 | G5: =G4+IFERROR(E5,0)-IFERROR(F5,0)
A6: 46082 | B6: Receita | C6: PIX | D6: Vendas do dia (dom) | E6: 2735.48 | G6: =G5+IFERROR(E6,0)-IFERROR(F6,0)
A7: 46082 | B7: Receita | C7: Dinheiro | D7: Vendas do dia (dom) | E7: 759.86 | G7: =G6+IFERROR(E7,0)-IFERROR(F7,0)
A8: 46083 | B8: Fornecedor | C8: Hortifruti | D8: Feira semanal — Ceasa | F8: 1343.59 | G8: =G7+IFERROR(E8,0)-IFERROR(F8,0)
A9: 46083 | B9: Fornecedor | C9: Bebidas | D9: Distribuidora Norte | F9: 4130.87 | G9: =G8+IFERROR(E9,0)-IFERROR(F9,0)
A10: 46083 | B10: Receita | C10: Cartão crédito | D10: Vendas do dia (seg) | E10: 1591.88 | G10: =G9+IFERROR(E10,0)-IFERROR(F10,0)
A11: 46083 | B11: Receita | C11: Cartão débito | D11: Vendas do dia (seg) | E11: 778.25 | G11: =G10+IFERROR(E11,0)-IFERROR(F11,0)
A12: 46083 | B12: Receita | C12: PIX | D12: Vendas do dia (seg) | E12: 636.75 | G12: =G11+IFERROR(E12,0)-IFERROR(F12,0)
A13: 46083 | B13: Receita | C13: Dinheiro | D13: Vendas do dia (seg) | E13: 176.88 | G13: =G12+IFERROR(E13,0)-IFERROR(F13,0)
A14: 46084 | B14: Fornecedor | C14: Cárneas | D14: Açougue Boi Forte | F14: 2522.27 | G14: =G13+IFERROR(E14,0)-IFERROR(F14,0)
A15: 46084 | B15: Receita | C15: Cartão crédito | D15: Vendas do dia (ter) | E15: 2272.53 | G15: =G14+IFERROR(E15,0)-IFERROR(F15,0)
A16: 46084 | B16: Receita | C16: Cartão débito | D16: Vendas do dia (ter) | E16: 1111.01 | G16: =G15+IFERROR(E16,0)-IFERROR(F16,0)
A17: 46084 | B17: Receita | C17: PIX | D17: Vendas do dia (ter) | E17: 909.01 | G17: =G16+IFERROR(E17,0)-IFERROR(F17,0)
A18: 46084 | B18: Receita | C18: Dinheiro | D18: Vendas do dia (ter) | E18: 252.5 | G18: =G17+IFERROR(E18,0)-IFERROR(F18,0)
A19: 46084 | B19: Receita | C19: iFood | D19: Repasse semanal iFood | E19: 5946.42 | G19: =G18+IFERROR(E19,0)-IFERROR(F19,0)
A20: 46085 | B20: Despesa fixa | C20: Outras operacionais | D20: Despesas operacionais diversas | F20: 2884.58 | G20: =G19+IFERROR(E20,0)-IFERROR(F20,0)
A21: 46085 | B21: Fornecedor | C21: Hortifruti | D21: Reposição hortifruti | F21: 1005 | G21: =G20+IFERROR(E21,0)-IFERROR(F21,0)
A22: 46085 | B22: Fornecedor | C22: Mercearia | D22: Atacado mercearia | F22: 2003.58 | G22: =G21+IFERROR(E22,0)-IFERROR(F22,0)
A23: 46085 | B23: Receita | C23: Cartão crédito | D23: Vendas do dia (qua) | E23: 2687.82 | G23: =G22+IFERROR(E23,0)-IFERROR(F23,0)
A24: 46085 | B24: Receita | C24: Cartão débito | D24: Vendas do dia (qua) | E24: 1314.05 | G24: =G23+IFERROR(E24,0)-IFERROR(F24,0)
A25: 46085 | B25: Receita | C25: PIX | D25: Vendas do dia (qua) | E25: 1075.13 | G25: =G24+IFERROR(E25,0)-IFERROR(F25,0)
A26: 46085 | B26: Receita | C26: Dinheiro | D26: Vendas do dia (qua) | E26: 298.65 | G26: =G25+IFERROR(E26,0)-IFERROR(F26,0)
A27: 46086 | B27: Despesa fixa | C27: Aluguel | D27: Aluguel mar/2026 | F27: 18000 | G27: =G26+IFERROR(E27,0)-IFERROR(F27,0)
A28: 46086 | B28: Receita | C28: Cartão crédito | D28: Vendas do dia (qui) | E28: 3686.29 | G28: =G27+IFERROR(E28,0)-IFERROR(F28,0)
A29: 46086 | B29: Receita | C29: Cartão débito | D29: Vendas do dia (qui) | E29: 1802.18 | G29: =G28+IFERROR(E29,0)-IFERROR(F29,0)
A30: 46086 | B30: Receita | C30: PIX | D30: Vendas do dia (qui) | E30: 1474.51 | G30: =G29+IFERROR(E30,0)-IFERROR(F30,0)
A31: 46086 | B31: Receita | C31: Dinheiro | D31: Vendas do dia (qui) | E31: 409.59 | G31: =G30+IFERROR(E31,0)-IFERROR(F31,0)
A32: 46087 | B32: Fornecedor | C32: Cárneas | D32: Açougue Boi Forte | F32: 2847.25 | G32: =G31+IFERROR(E32,0)-IFERROR(F32,0)
A33: 46087 | B33: Fornecedor | C33: Laticínios | D33: Laticínios semana | F33: 1199.71 | G33: =G32+IFERROR(E33,0)-IFERROR(F33,0)
A34: 46087 | B34: Receita | C34: Cartão crédito | D34: Vendas do dia (sex) | E34: 5254.44 | G34: =G33+IFERROR(E34,0)-IFERROR(F34,0)
A35: 46087 | B35: Receita | C35: Cartão débito | D35: Vendas do dia (sex) | E35: 2568.84 | G35: =G34+IFERROR(E35,0)-IFERROR(F35,0)
A36: 46087 | B36: Receita | C36: PIX | D36: Vendas do dia (sex) | E36: 2101.78 | G36: =G35+IFERROR(E36,0)-IFERROR(F36,0)
A37: 46087 | B37: Receita | C37: Dinheiro | D37: Vendas do dia (sex) | E37: 583.83 | G37: =G36+IFERROR(E37,0)-IFERROR(F37,0)
A38: 46088 | B38: Despesa variável | C38: Comissão | D38: Comissão garçom (sáb) | F38: 1139.25 | G38: =G37+IFERROR(E38,0)-IFERROR(F38,0)
A39: 46088 | B39: Receita | C39: Cartão crédito | D39: Vendas do dia (sáb) | E39: 6495.61 | G39: =G38+IFERROR(E39,0)-IFERROR(F39,0)
A40: 46088 | B40: Receita | C40: Cartão débito | D40: Vendas do dia (sáb) | E40: 3175.63 | G40: =G39+IFERROR(E40,0)-IFERROR(F40,0)
...

Sheet Resumo Mensal
A1: Mês | B1: Receita Bruta R$ | C1: Total Despesas R$ | D1: Saldo Mensal R$
A2: Março/2026 | B2: =SUMIFS('Fluxo Diário'!E2:E568,'Fluxo Diário'!A2:A568,">="&DATE(2026,3,1),'Fluxo Diário'!A2:A568,"<="&DATE(2026,3,31)) | C2: =SUMIFS('Fluxo Diário'!F2:F568,'Fluxo Diário'!A2:A568,">="&DATE(2026,3,1),'Fluxo Diário'!A2:A568,"<="&DATE(2026,3,31)) | D2: =B2-C2
A3: Abril/2026 | B3: =SUMIFS('Fluxo Diário'!E2:E568,'Fluxo Diário'!A2:A568,">="&DATE(2026,4,1),'Fluxo Diário'!A2:A568,"<="&DATE(2026,4,30)) | C3: =SUMIFS('Fluxo Diário'!F2:F568,'Fluxo Diário'!A2:A568,">="&DATE(2026,4,1),'Fluxo Diário'!A2:A568,"<="&DATE(2026,4,30)) | D3: =B3-C3
A4: Maio/2026 | B4: =SUMIFS('Fluxo Diário'!E2:E568,'Fluxo Diário'!A2:A568,">="&DATE(2026,5,1),'Fluxo Diário'!A2:A568,"<="&DATE(2026,5,31)) | C4: =SUMIFS('Fluxo Diário'!F2:F568,'Fluxo Diário'!A2:A568,">="&DATE(2026,5,1),'Fluxo Diário'!A2:A568,"<="&DATE(2026,5,31)) | D4: =B4-C4
A5: TOTAL 3M | B5: =SUM(B2:B4) | C5: =SUM(C2:C4) | D5: =SUM(D2:D4)
